[2021-12-06 13:50:46,629] {taskinstance.py:876} INFO - Dependencies all met for <TaskInstance: trigger_rule.task_2 2021-12-06T13:50:40.168394+00:00 [queued]>
[2021-12-06 13:50:46,977] {taskinstance.py:876} INFO - Dependencies all met for <TaskInstance: trigger_rule.task_2 2021-12-06T13:50:40.168394+00:00 [queued]>
[2021-12-06 13:50:46,995] {taskinstance.py:1067} INFO - 
--------------------------------------------------------------------------------
[2021-12-06 13:50:46,995] {taskinstance.py:1068} INFO - Starting attempt 1 of 1
[2021-12-06 13:50:46,995] {taskinstance.py:1069} INFO - 
--------------------------------------------------------------------------------
[2021-12-06 13:50:47,156] {taskinstance.py:1087} INFO - Executing <Task(BashOperator): task_2> on 2021-12-06T13:50:40.168394+00:00
[2021-12-06 13:50:47,251] {standard_task_runner.py:52} INFO - Started process 58954 to run task
[2021-12-06 13:50:47,803] {standard_task_runner.py:76} INFO - Running: ['airflow', 'tasks', 'run', 'trigger_rule', 'task_2', '2021-12-06T13:50:40.168394+00:00', '--job-id', '761', '--pool', 'default_pool', '--raw', '--subdir', 'DAGS_FOLDER/trigger_rule.py', '--cfg-path', '/tmp/tmpgkzgcec0', '--error-file', '/tmp/tmpe_dynyb2']
[2021-12-06 13:50:47,806] {standard_task_runner.py:77} INFO - Job 761: Subtask task_2
[2021-12-06 13:50:49,813] {logging_mixin.py:104} INFO - Running <TaskInstance: trigger_rule.task_2 2021-12-06T13:50:40.168394+00:00 [running]> on host airflowvm
[2021-12-06 13:50:51,978] {taskinstance.py:1280} INFO - Exporting the following env vars:
AIRFLOW_CTX_DAG_OWNER=airflow
AIRFLOW_CTX_DAG_ID=trigger_rule
AIRFLOW_CTX_TASK_ID=task_2
AIRFLOW_CTX_EXECUTION_DATE=2021-12-06T13:50:40.168394+00:00
AIRFLOW_CTX_DAG_RUN_ID=manual__2021-12-06T13:50:40.168394+00:00
[2021-12-06 13:50:51,980] {subprocess.py:52} INFO - Tmp dir root location: 
 /tmp
[2021-12-06 13:50:52,010] {subprocess.py:63} INFO - Running command: ['bash', '-c', 'exit 0']
[2021-12-06 13:50:52,138] {subprocess.py:75} INFO - Output:
[2021-12-06 13:50:52,381] {subprocess.py:83} INFO - Command exited with return code 0
[2021-12-06 13:50:53,187] {taskinstance.py:1184} INFO - Marking task as SUCCESS. dag_id=trigger_rule, task_id=task_2, execution_date=20211206T135040, start_date=20211206T135046, end_date=20211206T135053
[2021-12-06 13:50:54,593] {local_task_job.py:196} WARNING - State of this instance has been externally set to success. Terminating instance.
[2021-12-06 13:50:55,170] {process_utils.py:100} INFO - Sending Signals.SIGTERM to GPID 58954
[2021-12-06 13:50:55,239] {taskinstance.py:1264} ERROR - Received SIGTERM. Terminating subprocesses.
[2021-12-06 13:50:55,243] {subprocess.py:89} INFO - Sending SIGTERM signal to process group
[2021-12-06 13:50:55,281] {base.py:272} ERROR - Exception closing connection <connection object at 0x7fdccc559b80; dsn: 'user=postgres password=xxx dbname=postgres host=localhost', closed: 1>
Traceback (most recent call last):
  File "/home/airflow/sandbox/lib/python3.8/site-packages/sqlalchemy/pool/base.py", line 270, in _close_connection
    self._dialect.do_close(connection)
  File "/home/airflow/sandbox/lib/python3.8/site-packages/sqlalchemy/engine/default.py", line 564, in do_close
    dbapi_connection.close()
  File "/home/airflow/sandbox/lib/python3.8/site-packages/airflow/models/taskinstance.py", line 1265, in signal_handler
    task_copy.on_kill()
  File "/home/airflow/sandbox/lib/python3.8/site-packages/airflow/operators/bash.py", line 184, in on_kill
    self.subprocess_hook.send_sigterm()
  File "/home/airflow/sandbox/lib/python3.8/site-packages/airflow/hooks/subprocess.py", line 91, in send_sigterm
    os.killpg(os.getpgid(self.sub_process.pid), signal.SIGTERM)
ProcessLookupError: [Errno 3] No such process
[2021-12-06 13:50:55,561] {taskinstance.py:1245} INFO - 1 downstream tasks scheduled from follow-on schedule check
[2021-12-06 13:50:55,736] {process_utils.py:66} INFO - Process psutil.Process(pid=58954, status='terminated', exitcode=0, started='13:50:46') (58954) terminated with exit code 0
